<?xml version="1.0" encoding="UTF-8"?>
<testng-results skipped="0" failed="2" ignored="0" total="4" passed="2">
  <reporter-output>
  </reporter-output>
  <suite name="Suite" duration-ms="53190" started-at="2020-02-25T14:01:00Z" finished-at="2020-02-25T14:01:53Z">
    <groups>
    </groups>
    <test name="Test" duration-ms="53190" started-at="2020-02-25T14:01:00Z" finished-at="2020-02-25T14:01:53Z">
      <class name="Cases.CaseOne">
        <test-method status="PASS" signature="init()[pri:0, instance:Cases.CaseOne@6500df86]" name="init" is-config="true" duration-ms="8602" started-at="2020-02-25T14:01:00Z" finished-at="2020-02-25T14:01:08Z">
          <reporter-output>
          </reporter-output>
        </test-method> <!-- init -->
        <test-method status="FAIL" signature="caseFour()[pri:0, instance:Cases.CaseOne@6500df86]" name="caseFour" duration-ms="10" started-at="2020-02-25T14:01:08Z" finished-at="2020-02-25T14:01:08Z">
          <exception class="java.lang.AssertionError">
            <message>
              <![CDATA[expected [false] but found [true]]]>
            </message>
            <full-stacktrace>
              <![CDATA[java.lang.AssertionError: expected [false] but found [true]
at org.testng.Assert.fail(Assert.java:96)
at org.testng.Assert.failNotEquals(Assert.java:776)
at org.testng.Assert.assertEqualsImpl(Assert.java:137)
at org.testng.Assert.assertEquals(Assert.java:118)
at org.testng.Assert.assertEquals(Assert.java:568)
at org.testng.Assert.assertEquals(Assert.java:578)
at Cases.CaseOne.caseFour(CaseOne.java:52)
at sun.reflect.NativeMethodAccessorImpl.invoke0(Native Method)
at sun.reflect.NativeMethodAccessorImpl.invoke(NativeMethodAccessorImpl.java:62)
at sun.reflect.DelegatingMethodAccessorImpl.invoke(DelegatingMethodAccessorImpl.java:43)
at java.lang.reflect.Method.invoke(Method.java:497)
at org.testng.internal.MethodInvocationHelper.invokeMethod(MethodInvocationHelper.java:124)
at org.testng.internal.Invoker.invokeMethod(Invoker.java:583)
at org.testng.internal.Invoker.invokeTestMethod(Invoker.java:719)
at org.testng.internal.Invoker.invokeTestMethods(Invoker.java:989)
at org.testng.internal.TestMethodWorker.invokeTestMethods(TestMethodWorker.java:125)
at org.testng.internal.TestMethodWorker.run(TestMethodWorker.java:109)
at org.testng.TestRunner.privateRun(TestRunner.java:648)
at org.testng.TestRunner.run(TestRunner.java:505)
at org.testng.SuiteRunner.runTest(SuiteRunner.java:455)
at org.testng.SuiteRunner.runSequentially(SuiteRunner.java:450)
at org.testng.SuiteRunner.privateRun(SuiteRunner.java:415)
at org.testng.SuiteRunner.run(SuiteRunner.java:364)
at org.testng.SuiteRunnerWorker.runSuite(SuiteRunnerWorker.java:52)
at org.testng.SuiteRunnerWorker.run(SuiteRunnerWorker.java:84)
at org.testng.TestNG.runSuitesSequentially(TestNG.java:1208)
at org.testng.TestNG.runSuitesLocally(TestNG.java:1137)
at org.testng.TestNG.runSuites(TestNG.java:1049)
at org.testng.TestNG.run(TestNG.java:1017)
at org.testng.remote.AbstractRemoteTestNG.run(AbstractRemoteTestNG.java:115)
at org.testng.remote.RemoteTestNG.initAndRun(RemoteTestNG.java:251)
at org.testng.remote.RemoteTestNG.main(RemoteTestNG.java:77)
]]>
            </full-stacktrace>
          </exception> <!-- java.lang.AssertionError -->
          <reporter-output>
          </reporter-output>
        </test-method> <!-- caseFour -->
        <test-method status="PASS" signature="tearDown()[pri:0, instance:Cases.CaseOne@6500df86]" name="tearDown" is-config="true" duration-ms="927" started-at="2020-02-25T14:01:09Z" finished-at="2020-02-25T14:01:10Z">
          <reporter-output>
          </reporter-output>
        </test-method> <!-- tearDown -->
        <test-method status="PASS" signature="init()[pri:0, instance:Cases.CaseOne@6500df86]" name="init" is-config="true" duration-ms="16405" started-at="2020-02-25T14:01:10Z" finished-at="2020-02-25T14:01:27Z">
          <reporter-output>
          </reporter-output>
        </test-method> <!-- init -->
        <test-method status="PASS" signature="caseOne()[pri:0, instance:Cases.CaseOne@6500df86]" name="caseOne" duration-ms="3" started-at="2020-02-25T14:01:27Z" finished-at="2020-02-25T14:01:27Z">
          <reporter-output>
          </reporter-output>
        </test-method> <!-- caseOne -->
        <test-method status="PASS" signature="tearDown()[pri:0, instance:Cases.CaseOne@6500df86]" name="tearDown" is-config="true" duration-ms="979" started-at="2020-02-25T14:01:27Z" finished-at="2020-02-25T14:01:28Z">
          <reporter-output>
          </reporter-output>
        </test-method> <!-- tearDown -->
        <test-method status="PASS" signature="init()[pri:0, instance:Cases.CaseOne@6500df86]" name="init" is-config="true" duration-ms="7969" started-at="2020-02-25T14:01:28Z" finished-at="2020-02-25T14:01:36Z">
          <reporter-output>
          </reporter-output>
        </test-method> <!-- init -->
        <test-method status="PASS" signature="caseThree()[pri:0, instance:Cases.CaseOne@6500df86]" name="caseThree" duration-ms="2" started-at="2020-02-25T14:01:36Z" finished-at="2020-02-25T14:01:36Z">
          <reporter-output>
          </reporter-output>
        </test-method> <!-- caseThree -->
        <test-method status="PASS" signature="tearDown()[pri:0, instance:Cases.CaseOne@6500df86]" name="tearDown" is-config="true" duration-ms="1213" started-at="2020-02-25T14:01:36Z" finished-at="2020-02-25T14:01:37Z">
          <reporter-output>
          </reporter-output>
        </test-method> <!-- tearDown -->
        <test-method status="PASS" signature="init()[pri:0, instance:Cases.CaseOne@6500df86]" name="init" is-config="true" duration-ms="14512" started-at="2020-02-25T14:01:37Z" finished-at="2020-02-25T14:01:51Z">
          <reporter-output>
          </reporter-output>
        </test-method> <!-- init -->
        <test-method status="FAIL" signature="caseTwo()[pri:0, instance:Cases.CaseOne@6500df86]" name="caseTwo" duration-ms="3" started-at="2020-02-25T14:01:51Z" finished-at="2020-02-25T14:01:51Z">
          <exception class="java.lang.AssertionError">
            <message>
              <![CDATA[expected [false] but found [true]]]>
            </message>
            <full-stacktrace>
              <![CDATA[java.lang.AssertionError: expected [false] but found [true]
at org.testng.Assert.fail(Assert.java:96)
at org.testng.Assert.failNotEquals(Assert.java:776)
at org.testng.Assert.assertEqualsImpl(Assert.java:137)
at org.testng.Assert.assertEquals(Assert.java:118)
at org.testng.Assert.assertEquals(Assert.java:568)
at org.testng.Assert.assertEquals(Assert.java:578)
at Cases.CaseOne.caseTwo(CaseOne.java:42)
at sun.reflect.NativeMethodAccessorImpl.invoke0(Native Method)
at sun.reflect.NativeMethodAccessorImpl.invoke(NativeMethodAccessorImpl.java:62)
at sun.reflect.DelegatingMethodAccessorImpl.invoke(DelegatingMethodAccessorImpl.java:43)
at java.lang.reflect.Method.invoke(Method.java:497)
at org.testng.internal.MethodInvocationHelper.invokeMethod(MethodInvocationHelper.java:124)
at org.testng.internal.Invoker.invokeMethod(Invoker.java:583)
at org.testng.internal.Invoker.invokeTestMethod(Invoker.java:719)
at org.testng.internal.Invoker.invokeTestMethods(Invoker.java:989)
at org.testng.internal.TestMethodWorker.invokeTestMethods(TestMethodWorker.java:125)
at org.testng.internal.TestMethodWorker.run(TestMethodWorker.java:109)
at org.testng.TestRunner.privateRun(TestRunner.java:648)
at org.testng.TestRunner.run(TestRunner.java:505)
at org.testng.SuiteRunner.runTest(SuiteRunner.java:455)
at org.testng.SuiteRunner.runSequentially(SuiteRunner.java:450)
at org.testng.SuiteRunner.privateRun(SuiteRunner.java:415)
at org.testng.SuiteRunner.run(SuiteRunner.java:364)
at org.testng.SuiteRunnerWorker.runSuite(SuiteRunnerWorker.java:52)
at org.testng.SuiteRunnerWorker.run(SuiteRunnerWorker.java:84)
at org.testng.TestNG.runSuitesSequentially(TestNG.java:1208)
at org.testng.TestNG.runSuitesLocally(TestNG.java:1137)
at org.testng.TestNG.runSuites(TestNG.java:1049)
at org.testng.TestNG.run(TestNG.java:1017)
at org.testng.remote.AbstractRemoteTestNG.run(AbstractRemoteTestNG.java:115)
at org.testng.remote.RemoteTestNG.initAndRun(RemoteTestNG.java:251)
at org.testng.remote.RemoteTestNG.main(RemoteTestNG.java:77)
]]>
            </full-stacktrace>
          </exception> <!-- java.lang.AssertionError -->
          <reporter-output>
          </reporter-output>
        </test-method> <!-- caseTwo -->
        <test-method status="PASS" signature="tearDown()[pri:0, instance:Cases.CaseOne@6500df86]" name="tearDown" is-config="true" duration-ms="995" started-at="2020-02-25T14:01:52Z" finished-at="2020-02-25T14:01:53Z">
          <reporter-output>
          </reporter-output>
        </test-method> <!-- tearDown -->
      </class> <!-- Cases.CaseOne -->
    </test> <!-- Test -->
  </suite> <!-- Suite -->
</testng-results>
